2018-07-29 18:57:09 WARNING (Recorder) [homeassistant.components.recorder] Ended unfinished session (id=40 from 2018-07-24 07:22:44)
2018-07-29 18:57:20 ERROR (MainThread) [homeassistant.core] Error doing job: Task exception was never retrieved
Traceback (most recent call last):
  File "/usr/local/lib/python3.5/asyncio/tasks.py", line 239, in _step
    result = coro.send(None)
  File "/usr/local/lib/python3.5/site-packages/homeassistant/helpers/entity_platform.py", line 318, in _async_add_entity
    msg)
homeassistant.exceptions.HomeAssistantError: Entity id already exists: automation.notify_dani_when_wather_pump_is_opened
2018-07-29 18:57:23 ERROR (Thread-3) [homeassistant.components.sensor.bh1750] Bad writing in bus: 121
2018-07-29 18:57:23 ERROR (Thread-3) [homeassistant.components.sensor.bh1750] Bad writing in bus: 121
2018-07-29 18:57:23 ERROR (Thread-3) [homeassistant.components.sensor.bh1750] Bad writing in bus: 121
2018-07-29 18:57:23 ERROR (Thread-3) [homeassistant.components.sensor.bh1750] Bad writing in bus: 121
2018-07-29 18:57:23 ERROR (Thread-3) [homeassistant.components.sensor.bh1750] Bad writing in bus: 121
2018-07-29 18:57:23 ERROR (Thread-3) [homeassistant.components.sensor.bh1750] Bad writing in bus: 121
2018-07-29 18:57:23 ERROR (Thread-3) [homeassistant.components.sensor.bh1750] Bad writing in bus: 121
2018-07-29 18:57:23 ERROR (Thread-3) [homeassistant.components.sensor.bh1750] Bad writing in bus: 121
2018-07-29 18:57:24 ERROR (Thread-3) [homeassistant.components.sensor.bh1750] Bad reading in bus: 121
2018-07-29 18:57:24 ERROR (Thread-3) [homeassistant.components.sensor.bh1750] Bad writing in bus: 121
2018-07-29 18:57:24 ERROR (MainThread) [homeassistant.components.sensor.bh1750] BH1750 sensor not detected at 0x23
2018-07-29 18:57:40 WARNING (Thread-19) [netdisco.ssdp] Found malformed XML at http://192.168.1.209:45162: 
invalid request
2018-07-29 19:07:41 ERROR (Thread-12) [datadog.dogstatsd] Failed to send packet with a newly bound socket
Traceback (most recent call last):
  File "/home/homeassistant/.homeassistant/deps/lib/python3.5/site-packages/datadog/dogstatsd/base.py", line 267, in _send_to_server
    (self.socket or self.get_socket()).send(packet.encode(self.encoding))
ConnectionRefusedError: [Errno 111] Connection refused

During handling of the above exception, another exception occurred:

Traceback (most recent call last):
  File "/home/homeassistant/.homeassistant/deps/lib/python3.5/site-packages/datadog/dogstatsd/base.py", line 274, in _send_to_server
    self.get_socket().send(packet.encode(self.encoding))
ConnectionRefusedError: [Errno 111] Connection refused
2018-07-29 19:08:15 ERROR (Thread-12) [datadog.dogstatsd] Failed to send packet with a newly bound socket
Traceback (most recent call last):
  File "/home/homeassistant/.homeassistant/deps/lib/python3.5/site-packages/datadog/dogstatsd/base.py", line 267, in _send_to_server
    (self.socket or self.get_socket()).send(packet.encode(self.encoding))
ConnectionRefusedError: [Errno 111] Connection refused

During handling of the above exception, another exception occurred:

Traceback (most recent call last):
  File "/home/homeassistant/.homeassistant/deps/lib/python3.5/site-packages/datadog/dogstatsd/base.py", line 274, in _send_to_server
    self.get_socket().send(packet.encode(self.encoding))
ConnectionRefusedError: [Errno 111] Connection refused
2018-07-29 19:50:40 WARNING (MainThread) [asyncio] socket.send() raised exception.
2018-07-29 19:50:40 WARNING (MainThread) [asyncio] socket.send() raised exception.
2018-07-29 19:50:40 WARNING (MainThread) [asyncio] socket.send() raised exception.
2018-07-29 20:17:38 ERROR (MainThread) [aiohttp.server] Error handling request
Traceback (most recent call last):
  File "/usr/local/lib/python3.5/site-packages/aiohttp/web_protocol.py", line 378, in start
    resp = await self._request_handler(request)
  File "/usr/local/lib/python3.5/site-packages/aiohttp/web_app.py", line 341, in _handle
    resp = await handler(request)
  File "/usr/local/lib/python3.5/site-packages/aiohttp/web_middlewares.py", line 88, in impl
    return await handler(request)
  File "/usr/local/lib/python3.5/site-packages/homeassistant/components/http/static.py", line 67, in staticresource_middleware
    return await handler(request)
  File "/usr/local/lib/python3.5/site-packages/homeassistant/components/http/real_ip.py", line 34, in real_ip_middleware
    return await handler(request)
  File "/usr/local/lib/python3.5/site-packages/homeassistant/components/http/ban.py", line 68, in ban_middleware
    return await handler(request)
  File "/usr/local/lib/python3.5/site-packages/homeassistant/components/http/auth.py", line 61, in auth_middleware
    return await handler(request)
  File "/usr/local/lib/python3.5/site-packages/homeassistant/components/http/view.py", line 98, in handle
    result = await result
  File "/usr/local/lib/python3.5/site-packages/homeassistant/components/api.py", line 133, in get
    await response.write(msg.encode('UTF-8'))
  File "/usr/local/lib/python3.5/site-packages/aiohttp/web_response.py", line 380, in write
    await self._payload_writer.write(data)
  File "/usr/local/lib/python3.5/site-packages/aiohttp/http_writer.py", line 90, in write
    self._write(chunk)
  File "/usr/local/lib/python3.5/site-packages/aiohttp/http_writer.py", line 57, in _write
    raise ConnectionResetError('Cannot write to closing transport')
ConnectionResetError: Cannot write to closing transport
2018-07-29 20:17:38 ERROR (MainThread) [aiohttp.server] Unhandled exception
Traceback (most recent call last):
  File "/usr/local/lib/python3.5/site-packages/aiohttp/web_protocol.py", line 398, in start
    await resp.prepare(request)
  File "/usr/local/lib/python3.5/site-packages/aiohttp/web_response.py", line 300, in prepare
    return await self._start(request)
  File "/usr/local/lib/python3.5/site-packages/aiohttp/web_response.py", line 605, in _start
    return await super()._start(request)
  File "/usr/local/lib/python3.5/site-packages/aiohttp/web_response.py", line 367, in _start
    await writer.write_headers(status_line, headers)
  File "/usr/local/lib/python3.5/site-packages/aiohttp/http_writer.py", line 100, in write_headers
    self._write(buf)
  File "/usr/local/lib/python3.5/site-packages/aiohttp/http_writer.py", line 57, in _write
    raise ConnectionResetError('Cannot write to closing transport')
ConnectionResetError: Cannot write to closing transport
2018-07-29 21:50:33 ERROR (MainThread) [aiohttp.server] Error handling request
Traceback (most recent call last):
  File "/usr/local/lib/python3.5/site-packages/aiohttp/web_protocol.py", line 378, in start
    resp = await self._request_handler(request)
  File "/usr/local/lib/python3.5/site-packages/aiohttp/web_app.py", line 341, in _handle
    resp = await handler(request)
  File "/usr/local/lib/python3.5/site-packages/aiohttp/web_middlewares.py", line 88, in impl
    return await handler(request)
  File "/usr/local/lib/python3.5/site-packages/homeassistant/components/http/static.py", line 67, in staticresource_middleware
    return await handler(request)
  File "/usr/local/lib/python3.5/site-packages/homeassistant/components/http/real_ip.py", line 34, in real_ip_middleware
    return await handler(request)
  File "/usr/local/lib/python3.5/site-packages/homeassistant/components/http/ban.py", line 68, in ban_middleware
    return await handler(request)
  File "/usr/local/lib/python3.5/site-packages/homeassistant/components/http/auth.py", line 61, in auth_middleware
    return await handler(request)
  File "/usr/local/lib/python3.5/site-packages/homeassistant/components/http/view.py", line 98, in handle
    result = await result
  File "/usr/local/lib/python3.5/site-packages/homeassistant/components/api.py", line 133, in get
    await response.write(msg.encode('UTF-8'))
  File "/usr/local/lib/python3.5/site-packages/aiohttp/web_response.py", line 380, in write
    await self._payload_writer.write(data)
  File "/usr/local/lib/python3.5/site-packages/aiohttp/http_writer.py", line 90, in write
    self._write(chunk)
  File "/usr/local/lib/python3.5/site-packages/aiohttp/http_writer.py", line 57, in _write
    raise ConnectionResetError('Cannot write to closing transport')
ConnectionResetError: Cannot write to closing transport
2018-07-29 21:50:33 ERROR (MainThread) [aiohttp.server] Unhandled exception
Traceback (most recent call last):
  File "/usr/local/lib/python3.5/site-packages/aiohttp/web_protocol.py", line 398, in start
    await resp.prepare(request)
  File "/usr/local/lib/python3.5/site-packages/aiohttp/web_response.py", line 300, in prepare
    return await self._start(request)
  File "/usr/local/lib/python3.5/site-packages/aiohttp/web_response.py", line 605, in _start
    return await super()._start(request)
  File "/usr/local/lib/python3.5/site-packages/aiohttp/web_response.py", line 367, in _start
    await writer.write_headers(status_line, headers)
  File "/usr/local/lib/python3.5/site-packages/aiohttp/http_writer.py", line 100, in write_headers
    self._write(buf)
  File "/usr/local/lib/python3.5/site-packages/aiohttp/http_writer.py", line 57, in _write
    raise ConnectionResetError('Cannot write to closing transport')
ConnectionResetError: Cannot write to closing transport
2018-07-29 21:52:38 ERROR (MainThread) [homeassistant.core] Error executing service <ServiceCall notify.ios_dani: message=<homeassistant.helpers.template.Template object at 0x64b949f0>>
Traceback (most recent call last):
  File "/usr/local/lib/python3.5/site-packages/homeassistant/helpers/template.py", line 132, in async_render
    return self._compiled.render(kwargs).strip()
  File "/usr/local/lib/python3.5/site-packages/jinja2/environment.py", line 1008, in render
    return self.environment.handle_exception(exc_info, True)
  File "/usr/local/lib/python3.5/site-packages/jinja2/environment.py", line 780, in handle_exception
    reraise(exc_type, exc_value, tb)
  File "/usr/local/lib/python3.5/site-packages/jinja2/_compat.py", line 37, in reraise
    raise value.with_traceback(tb)
  File "<template>", line 1, in top-level template code
  File "/usr/local/lib/python3.5/site-packages/jinja2/sandbox.py", line 385, in getattr
    value = getattr(obj, attribute)
jinja2.exceptions.UndefinedError: 'sensor' is undefined

During handling of the above exception, another exception occurred:

Traceback (most recent call last):
  File "/usr/local/lib/python3.5/site-packages/homeassistant/core.py", line 1021, in _event_to_service_call
    await service_handler.func(service_call)
  File "/usr/local/lib/python3.5/site-packages/homeassistant/components/notify/__init__.py", line 134, in async_notify_message
    kwargs[ATTR_MESSAGE] = message.async_render()
  File "/usr/local/lib/python3.5/site-packages/homeassistant/helpers/template.py", line 134, in async_render
    raise TemplateError(err)
homeassistant.exceptions.TemplateError: UndefinedError: 'sensor' is undefined
2018-07-29 23:13:52 ERROR (MainThread) [homeassistant.core] Error executing service <ServiceCall notify.ios_dani: message=<homeassistant.helpers.template.Template object at 0x647cf870>>
Traceback (most recent call last):
  File "/usr/local/lib/python3.5/site-packages/homeassistant/helpers/template.py", line 132, in async_render
    return self._compiled.render(kwargs).strip()
  File "/usr/local/lib/python3.5/site-packages/jinja2/environment.py", line 1008, in render
    return self.environment.handle_exception(exc_info, True)
  File "/usr/local/lib/python3.5/site-packages/jinja2/environment.py", line 780, in handle_exception
    reraise(exc_type, exc_value, tb)
  File "/usr/local/lib/python3.5/site-packages/jinja2/_compat.py", line 37, in reraise
    raise value.with_traceback(tb)
  File "<template>", line 1, in top-level template code
  File "/usr/local/lib/python3.5/site-packages/jinja2/sandbox.py", line 385, in getattr
    value = getattr(obj, attribute)
jinja2.exceptions.UndefinedError: 'sensor' is undefined

During handling of the above exception, another exception occurred:

Traceback (most recent call last):
  File "/usr/local/lib/python3.5/site-packages/homeassistant/core.py", line 1021, in _event_to_service_call
    await service_handler.func(service_call)
  File "/usr/local/lib/python3.5/site-packages/homeassistant/components/notify/__init__.py", line 134, in async_notify_message
    kwargs[ATTR_MESSAGE] = message.async_render()
  File "/usr/local/lib/python3.5/site-packages/homeassistant/helpers/template.py", line 134, in async_render
    raise TemplateError(err)
homeassistant.exceptions.TemplateError: UndefinedError: 'sensor' is undefined
2018-07-29 23:53:23 ERROR (MainThread) [aiohttp.server] Error handling request
Traceback (most recent call last):
  File "/usr/local/lib/python3.5/site-packages/aiohttp/web_protocol.py", line 378, in start
    resp = await self._request_handler(request)
  File "/usr/local/lib/python3.5/site-packages/aiohttp/web_app.py", line 341, in _handle
    resp = await handler(request)
  File "/usr/local/lib/python3.5/site-packages/aiohttp/web_middlewares.py", line 88, in impl
    return await handler(request)
  File "/usr/local/lib/python3.5/site-packages/homeassistant/components/http/static.py", line 67, in staticresource_middleware
    return await handler(request)
  File "/usr/local/lib/python3.5/site-packages/homeassistant/components/http/real_ip.py", line 34, in real_ip_middleware
    return await handler(request)
  File "/usr/local/lib/python3.5/site-packages/homeassistant/components/http/ban.py", line 68, in ban_middleware
    return await handler(request)
  File "/usr/local/lib/python3.5/site-packages/homeassistant/components/http/auth.py", line 61, in auth_middleware
    return await handler(request)
  File "/usr/local/lib/python3.5/site-packages/homeassistant/components/http/view.py", line 98, in handle
    result = await result
  File "/usr/local/lib/python3.5/site-packages/homeassistant/components/api.py", line 133, in get
    await response.write(msg.encode('UTF-8'))
  File "/usr/local/lib/python3.5/site-packages/aiohttp/web_response.py", line 380, in write
    await self._payload_writer.write(data)
  File "/usr/local/lib/python3.5/site-packages/aiohttp/http_writer.py", line 90, in write
    self._write(chunk)
  File "/usr/local/lib/python3.5/site-packages/aiohttp/http_writer.py", line 57, in _write
    raise ConnectionResetError('Cannot write to closing transport')
ConnectionResetError: Cannot write to closing transport
2018-07-29 23:53:23 ERROR (MainThread) [aiohttp.server] Unhandled exception
Traceback (most recent call last):
  File "/usr/local/lib/python3.5/site-packages/aiohttp/web_protocol.py", line 398, in start
    await resp.prepare(request)
  File "/usr/local/lib/python3.5/site-packages/aiohttp/web_response.py", line 300, in prepare
    return await self._start(request)
  File "/usr/local/lib/python3.5/site-packages/aiohttp/web_response.py", line 605, in _start
    return await super()._start(request)
  File "/usr/local/lib/python3.5/site-packages/aiohttp/web_response.py", line 367, in _start
    await writer.write_headers(status_line, headers)
  File "/usr/local/lib/python3.5/site-packages/aiohttp/http_writer.py", line 100, in write_headers
    self._write(buf)
  File "/usr/local/lib/python3.5/site-packages/aiohttp/http_writer.py", line 57, in _write
    raise ConnectionResetError('Cannot write to closing transport')
ConnectionResetError: Cannot write to closing transport
2018-07-29 23:57:05 ERROR (MainThread) [homeassistant.core] Error executing service <ServiceCall notify.ios_dani: message=<homeassistant.helpers.template.Template object at 0x64bbe0b0>>
Traceback (most recent call last):
  File "/usr/local/lib/python3.5/site-packages/homeassistant/helpers/template.py", line 132, in async_render
    return self._compiled.render(kwargs).strip()
  File "/usr/local/lib/python3.5/site-packages/jinja2/environment.py", line 1008, in render
    return self.environment.handle_exception(exc_info, True)
  File "/usr/local/lib/python3.5/site-packages/jinja2/environment.py", line 780, in handle_exception
    reraise(exc_type, exc_value, tb)
  File "/usr/local/lib/python3.5/site-packages/jinja2/_compat.py", line 37, in reraise
    raise value.with_traceback(tb)
  File "<template>", line 1, in top-level template code
  File "/usr/local/lib/python3.5/site-packages/jinja2/sandbox.py", line 385, in getattr
    value = getattr(obj, attribute)
jinja2.exceptions.UndefinedError: 'sensor' is undefined

During handling of the above exception, another exception occurred:

Traceback (most recent call last):
  File "/usr/local/lib/python3.5/site-packages/homeassistant/core.py", line 1021, in _event_to_service_call
    await service_handler.func(service_call)
  File "/usr/local/lib/python3.5/site-packages/homeassistant/components/notify/__init__.py", line 134, in async_notify_message
    kwargs[ATTR_MESSAGE] = message.async_render()
  File "/usr/local/lib/python3.5/site-packages/homeassistant/helpers/template.py", line 134, in async_render
    raise TemplateError(err)
homeassistant.exceptions.TemplateError: UndefinedError: 'sensor' is undefined
2018-07-29 23:57:26 WARNING (MainThread) [hbmqtt.mqtt.protocol.handler] BrokerProtocolHandler Unhandled exception in reader coro: IncompleteReadError('0 bytes read on a total of 1 expected bytes',)
2018-07-29 23:57:28 ERROR (MainThread) [homeassistant.core] Error executing service <ServiceCall notify.ios_dani: message=<homeassistant.helpers.template.Template object at 0x64ba2c70>>
Traceback (most recent call last):
  File "/usr/local/lib/python3.5/site-packages/homeassistant/helpers/template.py", line 132, in async_render
    return self._compiled.render(kwargs).strip()
  File "/usr/local/lib/python3.5/site-packages/jinja2/environment.py", line 1008, in render
    return self.environment.handle_exception(exc_info, True)
  File "/usr/local/lib/python3.5/site-packages/jinja2/environment.py", line 780, in handle_exception
    reraise(exc_type, exc_value, tb)
  File "/usr/local/lib/python3.5/site-packages/jinja2/_compat.py", line 37, in reraise
    raise value.with_traceback(tb)
  File "<template>", line 1, in top-level template code
  File "/usr/local/lib/python3.5/site-packages/jinja2/sandbox.py", line 385, in getattr
    value = getattr(obj, attribute)
jinja2.exceptions.UndefinedError: 'sensor' is undefined

During handling of the above exception, another exception occurred:

Traceback (most recent call last):
  File "/usr/local/lib/python3.5/site-packages/homeassistant/core.py", line 1021, in _event_to_service_call
    await service_handler.func(service_call)
  File "/usr/local/lib/python3.5/site-packages/homeassistant/components/notify/__init__.py", line 134, in async_notify_message
    kwargs[ATTR_MESSAGE] = message.async_render()
  File "/usr/local/lib/python3.5/site-packages/homeassistant/helpers/template.py", line 134, in async_render
    raise TemplateError(err)
homeassistant.exceptions.TemplateError: UndefinedError: 'sensor' is undefined
2018-07-30 00:00:24 ERROR (MainThread) [aiohttp.server] Error handling request
Traceback (most recent call last):
  File "/usr/local/lib/python3.5/site-packages/aiohttp/web_protocol.py", line 378, in start
    resp = await self._request_handler(request)
  File "/usr/local/lib/python3.5/site-packages/aiohttp/web_app.py", line 341, in _handle
    resp = await handler(request)
  File "/usr/local/lib/python3.5/site-packages/aiohttp/web_middlewares.py", line 88, in impl
    return await handler(request)
  File "/usr/local/lib/python3.5/site-packages/homeassistant/components/http/static.py", line 67, in staticresource_middleware
    return await handler(request)
  File "/usr/local/lib/python3.5/site-packages/homeassistant/components/http/real_ip.py", line 34, in real_ip_middleware
    return await handler(request)
  File "/usr/local/lib/python3.5/site-packages/homeassistant/components/http/ban.py", line 68, in ban_middleware
    return await handler(request)
  File "/usr/local/lib/python3.5/site-packages/homeassistant/components/http/auth.py", line 61, in auth_middleware
    return await handler(request)
  File "/usr/local/lib/python3.5/site-packages/homeassistant/components/http/view.py", line 98, in handle
    result = await result
  File "/usr/local/lib/python3.5/site-packages/homeassistant/components/api.py", line 133, in get
    await response.write(msg.encode('UTF-8'))
  File "/usr/local/lib/python3.5/site-packages/aiohttp/web_response.py", line 380, in write
    await self._payload_writer.write(data)
  File "/usr/local/lib/python3.5/site-packages/aiohttp/http_writer.py", line 90, in write
    self._write(chunk)
  File "/usr/local/lib/python3.5/site-packages/aiohttp/http_writer.py", line 57, in _write
    raise ConnectionResetError('Cannot write to closing transport')
ConnectionResetError: Cannot write to closing transport
2018-07-30 00:00:24 ERROR (MainThread) [aiohttp.server] Unhandled exception
Traceback (most recent call last):
  File "/usr/local/lib/python3.5/site-packages/aiohttp/web_protocol.py", line 398, in start
    await resp.prepare(request)
  File "/usr/local/lib/python3.5/site-packages/aiohttp/web_response.py", line 300, in prepare
    return await self._start(request)
  File "/usr/local/lib/python3.5/site-packages/aiohttp/web_response.py", line 605, in _start
    return await super()._start(request)
  File "/usr/local/lib/python3.5/site-packages/aiohttp/web_response.py", line 367, in _start
    await writer.write_headers(status_line, headers)
  File "/usr/local/lib/python3.5/site-packages/aiohttp/http_writer.py", line 100, in write_headers
    self._write(buf)
  File "/usr/local/lib/python3.5/site-packages/aiohttp/http_writer.py", line 57, in _write
    raise ConnectionResetError('Cannot write to closing transport')
ConnectionResetError: Cannot write to closing transport
2018-07-30 00:01:08 ERROR (MainThread) [homeassistant.helpers.service] Error rendering data template: UndefinedError: 'sensor' is undefined
2018-07-30 00:02:15 ERROR (MainThread) [aiohttp.server] Error handling request
Traceback (most recent call last):
  File "/usr/local/lib/python3.5/site-packages/aiohttp/web_protocol.py", line 378, in start
    resp = await self._request_handler(request)
  File "/usr/local/lib/python3.5/site-packages/aiohttp/web_app.py", line 341, in _handle
    resp = await handler(request)
  File "/usr/local/lib/python3.5/site-packages/aiohttp/web_middlewares.py", line 88, in impl
    return await handler(request)
  File "/usr/local/lib/python3.5/site-packages/homeassistant/components/http/static.py", line 67, in staticresource_middleware
    return await handler(request)
  File "/usr/local/lib/python3.5/site-packages/homeassistant/components/http/real_ip.py", line 34, in real_ip_middleware
    return await handler(request)
  File "/usr/local/lib/python3.5/site-packages/homeassistant/components/http/ban.py", line 68, in ban_middleware
    return await handler(request)
  File "/usr/local/lib/python3.5/site-packages/homeassistant/components/http/auth.py", line 61, in auth_middleware
    return await handler(request)
  File "/usr/local/lib/python3.5/site-packages/homeassistant/components/http/view.py", line 98, in handle
    result = await result
  File "/usr/local/lib/python3.5/site-packages/homeassistant/components/api.py", line 133, in get
    await response.write(msg.encode('UTF-8'))
  File "/usr/local/lib/python3.5/site-packages/aiohttp/web_response.py", line 380, in write
    await self._payload_writer.write(data)
  File "/usr/local/lib/python3.5/site-packages/aiohttp/http_writer.py", line 90, in write
    self._write(chunk)
  File "/usr/local/lib/python3.5/site-packages/aiohttp/http_writer.py", line 57, in _write
    raise ConnectionResetError('Cannot write to closing transport')
ConnectionResetError: Cannot write to closing transport
2018-07-30 00:02:15 ERROR (MainThread) [aiohttp.server] Unhandled exception
Traceback (most recent call last):
  File "/usr/local/lib/python3.5/site-packages/aiohttp/web_protocol.py", line 398, in start
    await resp.prepare(request)
  File "/usr/local/lib/python3.5/site-packages/aiohttp/web_response.py", line 300, in prepare
    return await self._start(request)
  File "/usr/local/lib/python3.5/site-packages/aiohttp/web_response.py", line 605, in _start
    return await super()._start(request)
  File "/usr/local/lib/python3.5/site-packages/aiohttp/web_response.py", line 367, in _start
    await writer.write_headers(status_line, headers)
  File "/usr/local/lib/python3.5/site-packages/aiohttp/http_writer.py", line 100, in write_headers
    self._write(buf)
  File "/usr/local/lib/python3.5/site-packages/aiohttp/http_writer.py", line 57, in _write
    raise ConnectionResetError('Cannot write to closing transport')
ConnectionResetError: Cannot write to closing transport
2018-07-30 00:04:20 ERROR (MainThread) [aiohttp.server] Error handling request
Traceback (most recent call last):
  File "/usr/local/lib/python3.5/site-packages/aiohttp/web_protocol.py", line 378, in start
    resp = await self._request_handler(request)
  File "/usr/local/lib/python3.5/site-packages/aiohttp/web_app.py", line 341, in _handle
    resp = await handler(request)
  File "/usr/local/lib/python3.5/site-packages/aiohttp/web_middlewares.py", line 88, in impl
    return await handler(request)
  File "/usr/local/lib/python3.5/site-packages/homeassistant/components/http/static.py", line 67, in staticresource_middleware
    return await handler(request)
  File "/usr/local/lib/python3.5/site-packages/homeassistant/components/http/real_ip.py", line 34, in real_ip_middleware
    return await handler(request)
  File "/usr/local/lib/python3.5/site-packages/homeassistant/components/http/ban.py", line 68, in ban_middleware
    return await handler(request)
  File "/usr/local/lib/python3.5/site-packages/homeassistant/components/http/auth.py", line 61, in auth_middleware
    return await handler(request)
  File "/usr/local/lib/python3.5/site-packages/homeassistant/components/http/view.py", line 98, in handle
    result = await result
  File "/usr/local/lib/python3.5/site-packages/homeassistant/components/api.py", line 133, in get
    await response.write(msg.encode('UTF-8'))
  File "/usr/local/lib/python3.5/site-packages/aiohttp/web_response.py", line 380, in write
    await self._payload_writer.write(data)
  File "/usr/local/lib/python3.5/site-packages/aiohttp/http_writer.py", line 90, in write
    self._write(chunk)
  File "/usr/local/lib/python3.5/site-packages/aiohttp/http_writer.py", line 57, in _write
    raise ConnectionResetError('Cannot write to closing transport')
ConnectionResetError: Cannot write to closing transport
2018-07-30 00:04:21 ERROR (MainThread) [aiohttp.server] Unhandled exception
Traceback (most recent call last):
  File "/usr/local/lib/python3.5/site-packages/aiohttp/web_protocol.py", line 398, in start
    await resp.prepare(request)
  File "/usr/local/lib/python3.5/site-packages/aiohttp/web_response.py", line 300, in prepare
    return await self._start(request)
  File "/usr/local/lib/python3.5/site-packages/aiohttp/web_response.py", line 605, in _start
    return await super()._start(request)
  File "/usr/local/lib/python3.5/site-packages/aiohttp/web_response.py", line 367, in _start
    await writer.write_headers(status_line, headers)
  File "/usr/local/lib/python3.5/site-packages/aiohttp/http_writer.py", line 100, in write_headers
    self._write(buf)
  File "/usr/local/lib/python3.5/site-packages/aiohttp/http_writer.py", line 57, in _write
    raise ConnectionResetError('Cannot write to closing transport')
ConnectionResetError: Cannot write to closing transport
2018-07-30 00:04:21 WARNING (MainThread) [asyncio] socket.send() raised exception.
2018-07-30 00:04:21 WARNING (MainThread) [asyncio] socket.send() raised exception.
2018-07-30 00:04:21 WARNING (MainThread) [asyncio] socket.send() raised exception.
2018-07-30 00:05:37 ERROR (MainThread) [homeassistant.helpers.service] Error rendering data template: UndefinedError: 'sensor' is undefined
2018-07-30 00:08:31 ERROR (MainThread) [homeassistant.core] Error doing job: Task exception was never retrieved
Traceback (most recent call last):
  File "/usr/local/lib/python3.5/asyncio/tasks.py", line 239, in _step
    result = coro.send(None)
  File "/usr/local/lib/python3.5/site-packages/homeassistant/core.py", line 980, in _event_to_service_call
    domain = event.data.get(ATTR_DOMAIN).lower()
AttributeError: 'NoneType' object has no attribute 'lower'
2018-07-30 00:08:35 ERROR (MainThread) [homeassistant.core] Error doing job: Task exception was never retrieved
Traceback (most recent call last):
  File "/usr/local/lib/python3.5/asyncio/tasks.py", line 239, in _step
    result = coro.send(None)
  File "/usr/local/lib/python3.5/site-packages/homeassistant/core.py", line 980, in _event_to_service_call
    domain = event.data.get(ATTR_DOMAIN).lower()
AttributeError: 'NoneType' object has no attribute 'lower'
2018-07-30 00:10:31 ERROR (MainThread) [aiohttp.server] Error handling request
Traceback (most recent call last):
  File "/usr/local/lib/python3.5/site-packages/aiohttp/web_protocol.py", line 378, in start
    resp = await self._request_handler(request)
  File "/usr/local/lib/python3.5/site-packages/aiohttp/web_app.py", line 341, in _handle
    resp = await handler(request)
  File "/usr/local/lib/python3.5/site-packages/aiohttp/web_middlewares.py", line 88, in impl
    return await handler(request)
  File "/usr/local/lib/python3.5/site-packages/homeassistant/components/http/static.py", line 67, in staticresource_middleware
    return await handler(request)
  File "/usr/local/lib/python3.5/site-packages/homeassistant/components/http/real_ip.py", line 34, in real_ip_middleware
    return await handler(request)
  File "/usr/local/lib/python3.5/site-packages/homeassistant/components/http/ban.py", line 68, in ban_middleware
    return await handler(request)
  File "/usr/local/lib/python3.5/site-packages/homeassistant/components/http/auth.py", line 61, in auth_middleware
    return await handler(request)
  File "/usr/local/lib/python3.5/site-packages/homeassistant/components/http/view.py", line 98, in handle
    result = await result
  File "/usr/local/lib/python3.5/site-packages/homeassistant/components/api.py", line 223, in post
    hass.states.async_set(entity_id, new_state, attributes, force_update)
  File "/usr/local/lib/python3.5/site-packages/homeassistant/core.py", line 757, in async_set
    state = State(entity_id, new_state, attributes, last_changed)
  File "/usr/local/lib/python3.5/site-packages/homeassistant/core.py", line 556, in __init__
    self.attributes = MappingProxyType(attributes or {})
TypeError: mappingproxy() argument must be a mapping, not int
2018-07-30 00:13:47 ERROR (MainThread) [aiohttp.server] Error handling request
Traceback (most recent call last):
  File "/usr/local/lib/python3.5/site-packages/aiohttp/web_protocol.py", line 378, in start
    resp = await self._request_handler(request)
  File "/usr/local/lib/python3.5/site-packages/aiohttp/web_app.py", line 341, in _handle
    resp = await handler(request)
  File "/usr/local/lib/python3.5/site-packages/aiohttp/web_middlewares.py", line 88, in impl
    return await handler(request)
  File "/usr/local/lib/python3.5/site-packages/homeassistant/components/http/static.py", line 67, in staticresource_middleware
    return await handler(request)
  File "/usr/local/lib/python3.5/site-packages/homeassistant/components/http/real_ip.py", line 34, in real_ip_middleware
    return await handler(request)
  File "/usr/local/lib/python3.5/site-packages/homeassistant/components/http/ban.py", line 68, in ban_middleware
    return await handler(request)
  File "/usr/local/lib/python3.5/site-packages/homeassistant/components/http/auth.py", line 61, in auth_middleware
    return await handler(request)
  File "/usr/local/lib/python3.5/site-packages/homeassistant/components/http/view.py", line 98, in handle
    result = await result
  File "/usr/local/lib/python3.5/site-packages/homeassistant/components/api.py", line 133, in get
    await response.write(msg.encode('UTF-8'))
  File "/usr/local/lib/python3.5/site-packages/aiohttp/web_response.py", line 380, in write
    await self._payload_writer.write(data)
  File "/usr/local/lib/python3.5/site-packages/aiohttp/http_writer.py", line 90, in write
    self._write(chunk)
  File "/usr/local/lib/python3.5/site-packages/aiohttp/http_writer.py", line 57, in _write
    raise ConnectionResetError('Cannot write to closing transport')
ConnectionResetError: Cannot write to closing transport
2018-07-30 00:13:47 ERROR (MainThread) [aiohttp.server] Unhandled exception
Traceback (most recent call last):
  File "/usr/local/lib/python3.5/site-packages/aiohttp/web_protocol.py", line 398, in start
    await resp.prepare(request)
  File "/usr/local/lib/python3.5/site-packages/aiohttp/web_response.py", line 300, in prepare
    return await self._start(request)
  File "/usr/local/lib/python3.5/site-packages/aiohttp/web_response.py", line 605, in _start
    return await super()._start(request)
  File "/usr/local/lib/python3.5/site-packages/aiohttp/web_response.py", line 367, in _start
    await writer.write_headers(status_line, headers)
  File "/usr/local/lib/python3.5/site-packages/aiohttp/http_writer.py", line 100, in write_headers
    self._write(buf)
  File "/usr/local/lib/python3.5/site-packages/aiohttp/http_writer.py", line 57, in _write
    raise ConnectionResetError('Cannot write to closing transport')
ConnectionResetError: Cannot write to closing transport
2018-07-30 00:14:00 ERROR (MainThread) [homeassistant.core] Error executing service <ServiceCall notify.ios_dani: message=<homeassistant.helpers.template.Template object at 0x64a7ebf0>>
Traceback (most recent call last):
  File "/usr/local/lib/python3.5/site-packages/homeassistant/helpers/template.py", line 132, in async_render
    return self._compiled.render(kwargs).strip()
  File "/usr/local/lib/python3.5/site-packages/jinja2/environment.py", line 1008, in render
    return self.environment.handle_exception(exc_info, True)
  File "/usr/local/lib/python3.5/site-packages/jinja2/environment.py", line 780, in handle_exception
    reraise(exc_type, exc_value, tb)
  File "/usr/local/lib/python3.5/site-packages/jinja2/_compat.py", line 37, in reraise
    raise value.with_traceback(tb)
  File "<template>", line 1, in top-level template code
  File "/usr/local/lib/python3.5/site-packages/jinja2/sandbox.py", line 385, in getattr
    value = getattr(obj, attribute)
jinja2.exceptions.UndefinedError: 'sensor' is undefined

During handling of the above exception, another exception occurred:

Traceback (most recent call last):
  File "/usr/local/lib/python3.5/site-packages/homeassistant/core.py", line 1021, in _event_to_service_call
    await service_handler.func(service_call)
  File "/usr/local/lib/python3.5/site-packages/homeassistant/components/notify/__init__.py", line 134, in async_notify_message
    kwargs[ATTR_MESSAGE] = message.async_render()
  File "/usr/local/lib/python3.5/site-packages/homeassistant/helpers/template.py", line 134, in async_render
    raise TemplateError(err)
homeassistant.exceptions.TemplateError: UndefinedError: 'sensor' is undefined
2018-07-30 00:14:35 ERROR (MainThread) [aiohttp.server] Error handling request
Traceback (most recent call last):
  File "/usr/local/lib/python3.5/site-packages/aiohttp/web_protocol.py", line 378, in start
    resp = await self._request_handler(request)
  File "/usr/local/lib/python3.5/site-packages/aiohttp/web_app.py", line 341, in _handle
    resp = await handler(request)
  File "/usr/local/lib/python3.5/site-packages/aiohttp/web_middlewares.py", line 88, in impl
    return await handler(request)
  File "/usr/local/lib/python3.5/site-packages/homeassistant/components/http/static.py", line 67, in staticresource_middleware
    return await handler(request)
  File "/usr/local/lib/python3.5/site-packages/homeassistant/components/http/real_ip.py", line 34, in real_ip_middleware
    return await handler(request)
  File "/usr/local/lib/python3.5/site-packages/homeassistant/components/http/ban.py", line 68, in ban_middleware
    return await handler(request)
  File "/usr/local/lib/python3.5/site-packages/homeassistant/components/http/auth.py", line 61, in auth_middleware
    return await handler(request)
  File "/usr/local/lib/python3.5/site-packages/homeassistant/components/http/view.py", line 98, in handle
    result = await result
  File "/usr/local/lib/python3.5/site-packages/homeassistant/components/api.py", line 133, in get
    await response.write(msg.encode('UTF-8'))
  File "/usr/local/lib/python3.5/site-packages/aiohttp/web_response.py", line 380, in write
    await self._payload_writer.write(data)
  File "/usr/local/lib/python3.5/site-packages/aiohttp/http_writer.py", line 90, in write
    self._write(chunk)
  File "/usr/local/lib/python3.5/site-packages/aiohttp/http_writer.py", line 57, in _write
    raise ConnectionResetError('Cannot write to closing transport')
ConnectionResetError: Cannot write to closing transport
2018-07-30 00:14:35 ERROR (MainThread) [aiohttp.server] Unhandled exception
Traceback (most recent call last):
  File "/usr/local/lib/python3.5/site-packages/aiohttp/web_protocol.py", line 398, in start
    await resp.prepare(request)
  File "/usr/local/lib/python3.5/site-packages/aiohttp/web_response.py", line 300, in prepare
    return await self._start(request)
  File "/usr/local/lib/python3.5/site-packages/aiohttp/web_response.py", line 605, in _start
    return await super()._start(request)
  File "/usr/local/lib/python3.5/site-packages/aiohttp/web_response.py", line 367, in _start
    await writer.write_headers(status_line, headers)
  File "/usr/local/lib/python3.5/site-packages/aiohttp/http_writer.py", line 100, in write_headers
    self._write(buf)
  File "/usr/local/lib/python3.5/site-packages/aiohttp/http_writer.py", line 57, in _write
    raise ConnectionResetError('Cannot write to closing transport')
ConnectionResetError: Cannot write to closing transport
2018-07-30 00:15:17 ERROR (MainThread) [aiohttp.server] Error handling request
Traceback (most recent call last):
  File "/usr/local/lib/python3.5/site-packages/aiohttp/web_protocol.py", line 378, in start
    resp = await self._request_handler(request)
  File "/usr/local/lib/python3.5/site-packages/aiohttp/web_app.py", line 341, in _handle
    resp = await handler(request)
  File "/usr/local/lib/python3.5/site-packages/aiohttp/web_middlewares.py", line 88, in impl
    return await handler(request)
  File "/usr/local/lib/python3.5/site-packages/homeassistant/components/http/static.py", line 67, in staticresource_middleware
    return await handler(request)
  File "/usr/local/lib/python3.5/site-packages/homeassistant/components/http/real_ip.py", line 34, in real_ip_middleware
    return await handler(request)
  File "/usr/local/lib/python3.5/site-packages/homeassistant/components/http/ban.py", line 68, in ban_middleware
    return await handler(request)
  File "/usr/local/lib/python3.5/site-packages/homeassistant/components/http/auth.py", line 61, in auth_middleware
    return await handler(request)
  File "/usr/local/lib/python3.5/site-packages/homeassistant/components/http/view.py", line 98, in handle
    result = await result
  File "/usr/local/lib/python3.5/site-packages/homeassistant/components/api.py", line 133, in get
    await response.write(msg.encode('UTF-8'))
  File "/usr/local/lib/python3.5/site-packages/aiohttp/web_response.py", line 380, in write
    await self._payload_writer.write(data)
  File "/usr/local/lib/python3.5/site-packages/aiohttp/http_writer.py", line 90, in write
    self._write(chunk)
  File "/usr/local/lib/python3.5/site-packages/aiohttp/http_writer.py", line 57, in _write
    raise ConnectionResetError('Cannot write to closing transport')
ConnectionResetError: Cannot write to closing transport
2018-07-30 00:15:17 ERROR (MainThread) [aiohttp.server] Unhandled exception
Traceback (most recent call last):
  File "/usr/local/lib/python3.5/site-packages/aiohttp/web_protocol.py", line 398, in start
    await resp.prepare(request)
  File "/usr/local/lib/python3.5/site-packages/aiohttp/web_response.py", line 300, in prepare
    return await self._start(request)
  File "/usr/local/lib/python3.5/site-packages/aiohttp/web_response.py", line 605, in _start
    return await super()._start(request)
  File "/usr/local/lib/python3.5/site-packages/aiohttp/web_response.py", line 367, in _start
    await writer.write_headers(status_line, headers)
  File "/usr/local/lib/python3.5/site-packages/aiohttp/http_writer.py", line 100, in write_headers
    self._write(buf)
  File "/usr/local/lib/python3.5/site-packages/aiohttp/http_writer.py", line 57, in _write
    raise ConnectionResetError('Cannot write to closing transport')
ConnectionResetError: Cannot write to closing transport
2018-07-30 00:15:20 ERROR (MainThread) [homeassistant.core] Error executing service <ServiceCall notify.ios_dani: message=<homeassistant.helpers.template.Template object at 0x684a8e10>>
Traceback (most recent call last):
  File "/usr/local/lib/python3.5/site-packages/homeassistant/helpers/template.py", line 132, in async_render
    return self._compiled.render(kwargs).strip()
  File "/usr/local/lib/python3.5/site-packages/jinja2/environment.py", line 1008, in render
    return self.environment.handle_exception(exc_info, True)
  File "/usr/local/lib/python3.5/site-packages/jinja2/environment.py", line 780, in handle_exception
    reraise(exc_type, exc_value, tb)
  File "/usr/local/lib/python3.5/site-packages/jinja2/_compat.py", line 37, in reraise
    raise value.with_traceback(tb)
  File "<template>", line 1, in top-level template code
  File "/usr/local/lib/python3.5/site-packages/jinja2/sandbox.py", line 385, in getattr
    value = getattr(obj, attribute)
jinja2.exceptions.UndefinedError: 'switch' is undefined

During handling of the above exception, another exception occurred:

Traceback (most recent call last):
  File "/usr/local/lib/python3.5/site-packages/homeassistant/core.py", line 1021, in _event_to_service_call
    await service_handler.func(service_call)
  File "/usr/local/lib/python3.5/site-packages/homeassistant/components/notify/__init__.py", line 134, in async_notify_message
    kwargs[ATTR_MESSAGE] = message.async_render()
  File "/usr/local/lib/python3.5/site-packages/homeassistant/helpers/template.py", line 134, in async_render
    raise TemplateError(err)
homeassistant.exceptions.TemplateError: UndefinedError: 'switch' is undefined
2018-07-30 00:15:30 ERROR (MainThread) [homeassistant.core] Error executing service <ServiceCall notify.ios_dani: message=<homeassistant.helpers.template.Template object at 0x64b53150>>
Traceback (most recent call last):
  File "/usr/local/lib/python3.5/site-packages/homeassistant/helpers/template.py", line 132, in async_render
    return self._compiled.render(kwargs).strip()
  File "/usr/local/lib/python3.5/site-packages/jinja2/environment.py", line 1008, in render
    return self.environment.handle_exception(exc_info, True)
  File "/usr/local/lib/python3.5/site-packages/jinja2/environment.py", line 780, in handle_exception
    reraise(exc_type, exc_value, tb)
  File "/usr/local/lib/python3.5/site-packages/jinja2/_compat.py", line 37, in reraise
    raise value.with_traceback(tb)
  File "<template>", line 1, in top-level template code
  File "/usr/local/lib/python3.5/site-packages/jinja2/sandbox.py", line 385, in getattr
    value = getattr(obj, attribute)
jinja2.exceptions.UndefinedError: 'switch' is undefined

During handling of the above exception, another exception occurred:

Traceback (most recent call last):
  File "/usr/local/lib/python3.5/site-packages/homeassistant/core.py", line 1021, in _event_to_service_call
    await service_handler.func(service_call)
  File "/usr/local/lib/python3.5/site-packages/homeassistant/components/notify/__init__.py", line 134, in async_notify_message
    kwargs[ATTR_MESSAGE] = message.async_render()
  File "/usr/local/lib/python3.5/site-packages/homeassistant/helpers/template.py", line 134, in async_render
    raise TemplateError(err)
homeassistant.exceptions.TemplateError: UndefinedError: 'switch' is undefined
2018-07-30 00:17:41 ERROR (Thread-8) [datadog.dogstatsd] Failed to send packet with a newly bound socket
Traceback (most recent call last):
  File "/home/homeassistant/.homeassistant/deps/lib/python3.5/site-packages/datadog/dogstatsd/base.py", line 267, in _send_to_server
    (self.socket or self.get_socket()).send(packet.encode(self.encoding))
ConnectionRefusedError: [Errno 111] Connection refused

During handling of the above exception, another exception occurred:

Traceback (most recent call last):
  File "/home/homeassistant/.homeassistant/deps/lib/python3.5/site-packages/datadog/dogstatsd/base.py", line 274, in _send_to_server
    self.get_socket().send(packet.encode(self.encoding))
ConnectionRefusedError: [Errno 111] Connection refused
2018-07-30 00:17:42 ERROR (MainThread) [aiohttp.server] Unhandled exception
Traceback (most recent call last):
  File "/usr/local/lib/python3.5/site-packages/homeassistant/components/api.py", line 125, in get
    payload = await to_write.get()
  File "/usr/local/lib/python3.5/asyncio/queues.py", line 167, in get
    yield from getter
  File "/usr/local/lib/python3.5/asyncio/futures.py", line 380, in __iter__
    yield self  # This tells Task to wait for completion.
  File "/usr/local/lib/python3.5/asyncio/tasks.py", line 304, in _wakeup
    future.result()
  File "/usr/local/lib/python3.5/asyncio/futures.py", line 285, in result
    raise CancelledError
concurrent.futures._base.CancelledError

During handling of the above exception, another exception occurred:

Traceback (most recent call last):
  File "/usr/local/lib/python3.5/site-packages/aiohttp/web_protocol.py", line 398, in start
    await resp.prepare(request)
  File "/usr/local/lib/python3.5/site-packages/aiohttp/web_response.py", line 300, in prepare
    return await self._start(request)
  File "/usr/local/lib/python3.5/site-packages/aiohttp/web_response.py", line 605, in _start
    return await super()._start(request)
  File "/usr/local/lib/python3.5/site-packages/aiohttp/web_response.py", line 367, in _start
    await writer.write_headers(status_line, headers)
  File "/usr/local/lib/python3.5/site-packages/aiohttp/http_writer.py", line 100, in write_headers
    self._write(buf)
  File "/usr/local/lib/python3.5/site-packages/aiohttp/http_writer.py", line 57, in _write
    raise ConnectionResetError('Cannot write to closing transport')
ConnectionResetError: Cannot write to closing transport
2018-07-30 00:17:44 ERROR (MainThread) [homeassistant.core] Error executing service <ServiceCall notify.ios_dani: message=<homeassistant.helpers.template.Template object at 0x64a68610>>
Traceback (most recent call last):
  File "/usr/local/lib/python3.5/site-packages/homeassistant/helpers/template.py", line 132, in async_render
    return self._compiled.render(kwargs).strip()
  File "/usr/local/lib/python3.5/site-packages/jinja2/environment.py", line 1008, in render
    return self.environment.handle_exception(exc_info, True)
  File "/usr/local/lib/python3.5/site-packages/jinja2/environment.py", line 780, in handle_exception
    reraise(exc_type, exc_value, tb)
  File "/usr/local/lib/python3.5/site-packages/jinja2/_compat.py", line 37, in reraise
    raise value.with_traceback(tb)
  File "<template>", line 1, in top-level template code
  File "/usr/local/lib/python3.5/site-packages/jinja2/sandbox.py", line 385, in getattr
    value = getattr(obj, attribute)
jinja2.exceptions.UndefinedError: 'sensor' is undefined

During handling of the above exception, another exception occurred:

Traceback (most recent call last):
  File "/usr/local/lib/python3.5/site-packages/homeassistant/core.py", line 1021, in _event_to_service_call
    await service_handler.func(service_call)
  File "/usr/local/lib/python3.5/site-packages/homeassistant/components/notify/__init__.py", line 134, in async_notify_message
    kwargs[ATTR_MESSAGE] = message.async_render()
  File "/usr/local/lib/python3.5/site-packages/homeassistant/helpers/template.py", line 134, in async_render
    raise TemplateError(err)
homeassistant.exceptions.TemplateError: UndefinedError: 'sensor' is undefined
2018-07-30 00:17:52 ERROR (MainThread) [homeassistant.core] Error executing service <ServiceCall notify.ios_dani: message=<homeassistant.helpers.template.Template object at 0x64ab1fb0>>
Traceback (most recent call last):
  File "/usr/local/lib/python3.5/site-packages/homeassistant/helpers/template.py", line 132, in async_render
    return self._compiled.render(kwargs).strip()
  File "/usr/local/lib/python3.5/site-packages/jinja2/environment.py", line 1008, in render
    return self.environment.handle_exception(exc_info, True)
  File "/usr/local/lib/python3.5/site-packages/jinja2/environment.py", line 780, in handle_exception
    reraise(exc_type, exc_value, tb)
  File "/usr/local/lib/python3.5/site-packages/jinja2/_compat.py", line 37, in reraise
    raise value.with_traceback(tb)
  File "<template>", line 1, in top-level template code
  File "/usr/local/lib/python3.5/site-packages/jinja2/sandbox.py", line 385, in getattr
    value = getattr(obj, attribute)
jinja2.exceptions.UndefinedError: 'sensor' is undefined

During handling of the above exception, another exception occurred:

Traceback (most recent call last):
  File "/usr/local/lib/python3.5/site-packages/homeassistant/core.py", line 1021, in _event_to_service_call
    await service_handler.func(service_call)
  File "/usr/local/lib/python3.5/site-packages/homeassistant/components/notify/__init__.py", line 134, in async_notify_message
    kwargs[ATTR_MESSAGE] = message.async_render()
  File "/usr/local/lib/python3.5/site-packages/homeassistant/helpers/template.py", line 134, in async_render
    raise TemplateError(err)
homeassistant.exceptions.TemplateError: UndefinedError: 'sensor' is undefined
2018-07-30 00:18:01 ERROR (MainThread) [homeassistant.core] Error executing service <ServiceCall notify.ios_dani: message=<homeassistant.helpers.template.Template object at 0x64c34c90>>
Traceback (most recent call last):
  File "/usr/local/lib/python3.5/site-packages/homeassistant/helpers/template.py", line 132, in async_render
    return self._compiled.render(kwargs).strip()
  File "/usr/local/lib/python3.5/site-packages/jinja2/environment.py", line 1008, in render
    return self.environment.handle_exception(exc_info, True)
  File "/usr/local/lib/python3.5/site-packages/jinja2/environment.py", line 780, in handle_exception
    reraise(exc_type, exc_value, tb)
  File "/usr/local/lib/python3.5/site-packages/jinja2/_compat.py", line 37, in reraise
    raise value.with_traceback(tb)
  File "<template>", line 1, in top-level template code
  File "/usr/local/lib/python3.5/site-packages/jinja2/sandbox.py", line 385, in getattr
    value = getattr(obj, attribute)
jinja2.exceptions.UndefinedError: 'sensor' is undefined

During handling of the above exception, another exception occurred:

Traceback (most recent call last):
  File "/usr/local/lib/python3.5/site-packages/homeassistant/core.py", line 1021, in _event_to_service_call
    await service_handler.func(service_call)
  File "/usr/local/lib/python3.5/site-packages/homeassistant/components/notify/__init__.py", line 134, in async_notify_message
    kwargs[ATTR_MESSAGE] = message.async_render()
  File "/usr/local/lib/python3.5/site-packages/homeassistant/helpers/template.py", line 134, in async_render
    raise TemplateError(err)
homeassistant.exceptions.TemplateError: UndefinedError: 'sensor' is undefined
2018-07-30 00:18:29 ERROR (MainThread) [aiohttp.server] Error handling request
Traceback (most recent call last):
  File "/usr/local/lib/python3.5/site-packages/aiohttp/web_protocol.py", line 378, in start
    resp = await self._request_handler(request)
  File "/usr/local/lib/python3.5/site-packages/aiohttp/web_app.py", line 341, in _handle
    resp = await handler(request)
  File "/usr/local/lib/python3.5/site-packages/aiohttp/web_middlewares.py", line 88, in impl
    return await handler(request)
  File "/usr/local/lib/python3.5/site-packages/homeassistant/components/http/static.py", line 67, in staticresource_middleware
    return await handler(request)
  File "/usr/local/lib/python3.5/site-packages/homeassistant/components/http/real_ip.py", line 34, in real_ip_middleware
    return await handler(request)
  File "/usr/local/lib/python3.5/site-packages/homeassistant/components/http/ban.py", line 68, in ban_middleware
    return await handler(request)
  File "/usr/local/lib/python3.5/site-packages/homeassistant/components/http/auth.py", line 61, in auth_middleware
    return await handler(request)
  File "/usr/local/lib/python3.5/site-packages/homeassistant/components/http/view.py", line 98, in handle
    result = await result
  File "/usr/local/lib/python3.5/site-packages/homeassistant/components/api.py", line 133, in get
    await response.write(msg.encode('UTF-8'))
  File "/usr/local/lib/python3.5/site-packages/aiohttp/web_response.py", line 380, in write
    await self._payload_writer.write(data)
  File "/usr/local/lib/python3.5/site-packages/aiohttp/http_writer.py", line 90, in write
    self._write(chunk)
  File "/usr/local/lib/python3.5/site-packages/aiohttp/http_writer.py", line 57, in _write
    raise ConnectionResetError('Cannot write to closing transport')
ConnectionResetError: Cannot write to closing transport
2018-07-30 00:18:29 ERROR (MainThread) [aiohttp.server] Unhandled exception
Traceback (most recent call last):
  File "/usr/local/lib/python3.5/site-packages/aiohttp/web_protocol.py", line 398, in start
    await resp.prepare(request)
  File "/usr/local/lib/python3.5/site-packages/aiohttp/web_response.py", line 300, in prepare
    return await self._start(request)
  File "/usr/local/lib/python3.5/site-packages/aiohttp/web_response.py", line 605, in _start
    return await super()._start(request)
  File "/usr/local/lib/python3.5/site-packages/aiohttp/web_response.py", line 367, in _start
    await writer.write_headers(status_line, headers)
  File "/usr/local/lib/python3.5/site-packages/aiohttp/http_writer.py", line 100, in write_headers
    self._write(buf)
  File "/usr/local/lib/python3.5/site-packages/aiohttp/http_writer.py", line 57, in _write
    raise ConnectionResetError('Cannot write to closing transport')
ConnectionResetError: Cannot write to closing transport
2018-07-30 00:18:32 ERROR (MainThread) [homeassistant.core] Error executing service <ServiceCall notify.ios_dani: message=<homeassistant.helpers.template.Template object at 0x64a70d50>>
Traceback (most recent call last):
  File "/usr/local/lib/python3.5/site-packages/homeassistant/helpers/template.py", line 132, in async_render
    return self._compiled.render(kwargs).strip()
  File "/usr/local/lib/python3.5/site-packages/jinja2/environment.py", line 1008, in render
    return self.environment.handle_exception(exc_info, True)
  File "/usr/local/lib/python3.5/site-packages/jinja2/environment.py", line 780, in handle_exception
    reraise(exc_type, exc_value, tb)
  File "/usr/local/lib/python3.5/site-packages/jinja2/_compat.py", line 37, in reraise
    raise value.with_traceback(tb)
  File "<template>", line 1, in top-level template code
  File "/usr/local/lib/python3.5/site-packages/jinja2/sandbox.py", line 385, in getattr
    value = getattr(obj, attribute)
jinja2.exceptions.UndefinedError: 'sensor' is undefined

During handling of the above exception, another exception occurred:

Traceback (most recent call last):
  File "/usr/local/lib/python3.5/site-packages/homeassistant/core.py", line 1021, in _event_to_service_call
    await service_handler.func(service_call)
  File "/usr/local/lib/python3.5/site-packages/homeassistant/components/notify/__init__.py", line 134, in async_notify_message
    kwargs[ATTR_MESSAGE] = message.async_render()
  File "/usr/local/lib/python3.5/site-packages/homeassistant/helpers/template.py", line 134, in async_render
    raise TemplateError(err)
homeassistant.exceptions.TemplateError: UndefinedError: 'sensor' is undefined
2018-07-30 00:19:23 ERROR (MainThread) [aiohttp.server] Error handling request
Traceback (most recent call last):
  File "/usr/local/lib/python3.5/site-packages/aiohttp/web_protocol.py", line 378, in start
    resp = await self._request_handler(request)
  File "/usr/local/lib/python3.5/site-packages/aiohttp/web_app.py", line 341, in _handle
    resp = await handler(request)
  File "/usr/local/lib/python3.5/site-packages/aiohttp/web_middlewares.py", line 88, in impl
    return await handler(request)
  File "/usr/local/lib/python3.5/site-packages/homeassistant/components/http/static.py", line 67, in staticresource_middleware
    return await handler(request)
  File "/usr/local/lib/python3.5/site-packages/homeassistant/components/http/real_ip.py", line 34, in real_ip_middleware
    return await handler(request)
  File "/usr/local/lib/python3.5/site-packages/homeassistant/components/http/ban.py", line 68, in ban_middleware
    return await handler(request)
  File "/usr/local/lib/python3.5/site-packages/homeassistant/components/http/auth.py", line 61, in auth_middleware
    return await handler(request)
  File "/usr/local/lib/python3.5/site-packages/homeassistant/components/http/view.py", line 98, in handle
    result = await result
  File "/usr/local/lib/python3.5/site-packages/homeassistant/components/api.py", line 133, in get
    await response.write(msg.encode('UTF-8'))
  File "/usr/local/lib/python3.5/site-packages/aiohttp/web_response.py", line 380, in write
    await self._payload_writer.write(data)
  File "/usr/local/lib/python3.5/site-packages/aiohttp/http_writer.py", line 90, in write
    self._write(chunk)
  File "/usr/local/lib/python3.5/site-packages/aiohttp/http_writer.py", line 57, in _write
    raise ConnectionResetError('Cannot write to closing transport')
ConnectionResetError: Cannot write to closing transport
2018-07-30 00:19:23 ERROR (MainThread) [aiohttp.server] Unhandled exception
Traceback (most recent call last):
  File "/usr/local/lib/python3.5/site-packages/aiohttp/web_protocol.py", line 398, in start
    await resp.prepare(request)
  File "/usr/local/lib/python3.5/site-packages/aiohttp/web_response.py", line 300, in prepare
    return await self._start(request)
  File "/usr/local/lib/python3.5/site-packages/aiohttp/web_response.py", line 605, in _start
    return await super()._start(request)
  File "/usr/local/lib/python3.5/site-packages/aiohttp/web_response.py", line 367, in _start
    await writer.write_headers(status_line, headers)
  File "/usr/local/lib/python3.5/site-packages/aiohttp/http_writer.py", line 100, in write_headers
    self._write(buf)
  File "/usr/local/lib/python3.5/site-packages/aiohttp/http_writer.py", line 57, in _write
    raise ConnectionResetError('Cannot write to closing transport')
ConnectionResetError: Cannot write to closing transport
2018-07-30 00:20:59 ERROR (MainThread) [aiohttp.server] Error handling request
Traceback (most recent call last):
  File "/usr/local/lib/python3.5/site-packages/aiohttp/web_protocol.py", line 378, in start
    resp = await self._request_handler(request)
  File "/usr/local/lib/python3.5/site-packages/aiohttp/web_app.py", line 341, in _handle
    resp = await handler(request)
  File "/usr/local/lib/python3.5/site-packages/aiohttp/web_middlewares.py", line 88, in impl
    return await handler(request)
  File "/usr/local/lib/python3.5/site-packages/homeassistant/components/http/static.py", line 67, in staticresource_middleware
    return await handler(request)
  File "/usr/local/lib/python3.5/site-packages/homeassistant/components/http/real_ip.py", line 34, in real_ip_middleware
    return await handler(request)
  File "/usr/local/lib/python3.5/site-packages/homeassistant/components/http/ban.py", line 68, in ban_middleware
    return await handler(request)
  File "/usr/local/lib/python3.5/site-packages/homeassistant/components/http/auth.py", line 61, in auth_middleware
    return await handler(request)
  File "/usr/local/lib/python3.5/site-packages/homeassistant/components/http/view.py", line 98, in handle
    result = await result
  File "/usr/local/lib/python3.5/site-packages/homeassistant/components/api.py", line 133, in get
    await response.write(msg.encode('UTF-8'))
  File "/usr/local/lib/python3.5/site-packages/aiohttp/web_response.py", line 380, in write
    await self._payload_writer.write(data)
  File "/usr/local/lib/python3.5/site-packages/aiohttp/http_writer.py", line 90, in write
    self._write(chunk)
  File "/usr/local/lib/python3.5/site-packages/aiohttp/http_writer.py", line 57, in _write
    raise ConnectionResetError('Cannot write to closing transport')
ConnectionResetError: Cannot write to closing transport
2018-07-30 00:20:59 ERROR (MainThread) [aiohttp.server] Unhandled exception
Traceback (most recent call last):
  File "/usr/local/lib/python3.5/site-packages/aiohttp/web_protocol.py", line 398, in start
    await resp.prepare(request)
  File "/usr/local/lib/python3.5/site-packages/aiohttp/web_response.py", line 300, in prepare
    return await self._start(request)
  File "/usr/local/lib/python3.5/site-packages/aiohttp/web_response.py", line 605, in _start
    return await super()._start(request)
  File "/usr/local/lib/python3.5/site-packages/aiohttp/web_response.py", line 367, in _start
    await writer.write_headers(status_line, headers)
  File "/usr/local/lib/python3.5/site-packages/aiohttp/http_writer.py", line 100, in write_headers
    self._write(buf)
  File "/usr/local/lib/python3.5/site-packages/aiohttp/http_writer.py", line 57, in _write
    raise ConnectionResetError('Cannot write to closing transport')
ConnectionResetError: Cannot write to closing transport
2018-07-30 01:34:57 ERROR (Thread-5) [datadog.dogstatsd] Failed to send packet with a newly bound socket
Traceback (most recent call last):
  File "/home/homeassistant/.homeassistant/deps/lib/python3.5/site-packages/datadog/dogstatsd/base.py", line 267, in _send_to_server
    (self.socket or self.get_socket()).send(packet.encode(self.encoding))
ConnectionRefusedError: [Errno 111] Connection refused

During handling of the above exception, another exception occurred:

Traceback (most recent call last):
  File "/home/homeassistant/.homeassistant/deps/lib/python3.5/site-packages/datadog/dogstatsd/base.py", line 274, in _send_to_server
    self.get_socket().send(packet.encode(self.encoding))
ConnectionRefusedError: [Errno 111] Connection refused
2018-07-30 07:52:20 WARNING (MainThread) [asyncio] socket.send() raised exception.
2018-07-30 07:52:20 WARNING (MainThread) [asyncio] socket.send() raised exception.
2018-07-30 07:52:20 WARNING (MainThread) [asyncio] socket.send() raised exception.
2018-07-30 07:52:20 WARNING (MainThread) [asyncio] socket.send() raised exception.
2018-07-30 07:52:20 WARNING (MainThread) [asyncio] socket.send() raised exception.
2018-07-30 07:52:20 WARNING (MainThread) [asyncio] socket.send() raised exception.
2018-07-30 07:52:20 WARNING (MainThread) [asyncio] socket.send() raised exception.
2018-07-30 07:52:20 WARNING (MainThread) [asyncio] socket.send() raised exception.
2018-07-30 09:59:34 ERROR (MainThread) [aiohttp.server] Error handling request
Traceback (most recent call last):
  File "/usr/local/lib/python3.5/site-packages/aiohttp/web_protocol.py", line 378, in start
    resp = await self._request_handler(request)
  File "/usr/local/lib/python3.5/site-packages/aiohttp/web_app.py", line 341, in _handle
    resp = await handler(request)
  File "/usr/local/lib/python3.5/site-packages/aiohttp/web_middlewares.py", line 88, in impl
    return await handler(request)
  File "/usr/local/lib/python3.5/site-packages/homeassistant/components/http/static.py", line 67, in staticresource_middleware
    return await handler(request)
  File "/usr/local/lib/python3.5/site-packages/homeassistant/components/http/real_ip.py", line 34, in real_ip_middleware
    return await handler(request)
  File "/usr/local/lib/python3.5/site-packages/homeassistant/components/http/ban.py", line 68, in ban_middleware
    return await handler(request)
  File "/usr/local/lib/python3.5/site-packages/homeassistant/components/http/auth.py", line 61, in auth_middleware
    return await handler(request)
  File "/usr/local/lib/python3.5/site-packages/homeassistant/components/http/view.py", line 98, in handle
    result = await result
  File "/usr/local/lib/python3.5/site-packages/homeassistant/components/api.py", line 133, in get
    await response.write(msg.encode('UTF-8'))
  File "/usr/local/lib/python3.5/site-packages/aiohttp/web_response.py", line 380, in write
    await self._payload_writer.write(data)
  File "/usr/local/lib/python3.5/site-packages/aiohttp/http_writer.py", line 90, in write
    self._write(chunk)
  File "/usr/local/lib/python3.5/site-packages/aiohttp/http_writer.py", line 57, in _write
    raise ConnectionResetError('Cannot write to closing transport')
ConnectionResetError: Cannot write to closing transport
2018-07-30 09:59:34 ERROR (MainThread) [aiohttp.server] Unhandled exception
Traceback (most recent call last):
  File "/usr/local/lib/python3.5/site-packages/aiohttp/web_protocol.py", line 398, in start
    await resp.prepare(request)
  File "/usr/local/lib/python3.5/site-packages/aiohttp/web_response.py", line 300, in prepare
    return await self._start(request)
  File "/usr/local/lib/python3.5/site-packages/aiohttp/web_response.py", line 605, in _start
    return await super()._start(request)
  File "/usr/local/lib/python3.5/site-packages/aiohttp/web_response.py", line 367, in _start
    await writer.write_headers(status_line, headers)
  File "/usr/local/lib/python3.5/site-packages/aiohttp/http_writer.py", line 100, in write_headers
    self._write(buf)
  File "/usr/local/lib/python3.5/site-packages/aiohttp/http_writer.py", line 57, in _write
    raise ConnectionResetError('Cannot write to closing transport')
ConnectionResetError: Cannot write to closing transport
2018-07-30 22:40:30 ERROR (Thread-18) [datadog.dogstatsd] Failed to send packet with a newly bound socket
Traceback (most recent call last):
  File "/home/homeassistant/.homeassistant/deps/lib/python3.5/site-packages/datadog/dogstatsd/base.py", line 267, in _send_to_server
    (self.socket or self.get_socket()).send(packet.encode(self.encoding))
ConnectionRefusedError: [Errno 111] Connection refused

During handling of the above exception, another exception occurred:

Traceback (most recent call last):
  File "/home/homeassistant/.homeassistant/deps/lib/python3.5/site-packages/datadog/dogstatsd/base.py", line 274, in _send_to_server
    self.get_socket().send(packet.encode(self.encoding))
ConnectionRefusedError: [Errno 111] Connection refused
2018-07-30 23:25:48 WARNING (MainThread) [asyncio] socket.send() raised exception.
2018-07-30 23:25:48 WARNING (MainThread) [asyncio] socket.send() raised exception.
2018-07-30 23:25:48 WARNING (MainThread) [asyncio] socket.send() raised exception.
2018-07-30 23:25:48 WARNING (MainThread) [asyncio] socket.send() raised exception.
2018-07-30 23:25:48 WARNING (MainThread) [asyncio] socket.send() raised exception.
2018-07-30 23:25:48 WARNING (MainThread) [asyncio] socket.send() raised exception.
2018-07-30 23:25:48 WARNING (MainThread) [asyncio] socket.send() raised exception.
2018-07-31 06:54:01 ERROR (Thread-12) [datadog.dogstatsd] Failed to send packet with a newly bound socket
Traceback (most recent call last):
  File "/home/homeassistant/.homeassistant/deps/lib/python3.5/site-packages/datadog/dogstatsd/base.py", line 267, in _send_to_server
    (self.socket or self.get_socket()).send(packet.encode(self.encoding))
ConnectionRefusedError: [Errno 111] Connection refused

During handling of the above exception, another exception occurred:

Traceback (most recent call last):
  File "/home/homeassistant/.homeassistant/deps/lib/python3.5/site-packages/datadog/dogstatsd/base.py", line 274, in _send_to_server
    self.get_socket().send(packet.encode(self.encoding))
ConnectionRefusedError: [Errno 111] Connection refused
2018-07-31 07:06:56 ERROR (Thread-22) [datadog.dogstatsd] Failed to send packet with a newly bound socket
Traceback (most recent call last):
  File "/home/homeassistant/.homeassistant/deps/lib/python3.5/site-packages/datadog/dogstatsd/base.py", line 267, in _send_to_server
    (self.socket or self.get_socket()).send(packet.encode(self.encoding))
ConnectionRefusedError: [Errno 111] Connection refused

During handling of the above exception, another exception occurred:

Traceback (most recent call last):
  File "/home/homeassistant/.homeassistant/deps/lib/python3.5/site-packages/datadog/dogstatsd/base.py", line 274, in _send_to_server
    self.get_socket().send(packet.encode(self.encoding))
ConnectionRefusedError: [Errno 111] Connection refused
2018-07-31 07:17:47 ERROR (Thread-9) [datadog.dogstatsd] Failed to send packet with a newly bound socket
Traceback (most recent call last):
  File "/home/homeassistant/.homeassistant/deps/lib/python3.5/site-packages/datadog/dogstatsd/base.py", line 267, in _send_to_server
    (self.socket or self.get_socket()).send(packet.encode(self.encoding))
ConnectionRefusedError: [Errno 111] Connection refused

During handling of the above exception, another exception occurred:

Traceback (most recent call last):
  File "/home/homeassistant/.homeassistant/deps/lib/python3.5/site-packages/datadog/dogstatsd/base.py", line 274, in _send_to_server
    self.get_socket().send(packet.encode(self.encoding))
ConnectionRefusedError: [Errno 111] Connection refused
2018-07-31 08:43:23 ERROR (Thread-19) [datadog.dogstatsd] Failed to send packet with a newly bound socket
Traceback (most recent call last):
  File "/home/homeassistant/.homeassistant/deps/lib/python3.5/site-packages/datadog/dogstatsd/base.py", line 267, in _send_to_server
    (self.socket or self.get_socket()).send(packet.encode(self.encoding))
ConnectionRefusedError: [Errno 111] Connection refused

During handling of the above exception, another exception occurred:

Traceback (most recent call last):
  File "/home/homeassistant/.homeassistant/deps/lib/python3.5/site-packages/datadog/dogstatsd/base.py", line 274, in _send_to_server
    self.get_socket().send(packet.encode(self.encoding))
ConnectionRefusedError: [Errno 111] Connection refused
2018-07-31 12:44:23 ERROR (MainThread) [homeassistant.core] Error doing job: Task exception was never retrieved
Traceback (most recent call last):
  File "/usr/local/lib/python3.5/asyncio/tasks.py", line 239, in _step
    result = coro.send(None)
  File "/home/homeassistant/.homeassistant/deps/lib/python3.5/site-packages/hbmqtt/broker.py", line 342, in stream_connected
    yield from self.client_connected(listener_name, StreamReaderAdapter(reader), StreamWriterAdapter(writer))
  File "/home/homeassistant/.homeassistant/deps/lib/python3.5/site-packages/hbmqtt/broker.py", line 357, in client_connected
    handler, client_session = yield from BrokerProtocolHandler.init_from_connect(reader, writer, self.plugins_manager, loop=self._loop)
  File "/home/homeassistant/.homeassistant/deps/lib/python3.5/site-packages/hbmqtt/mqtt/protocol/broker_handler.py", line 129, in init_from_connect
    connect = yield from ConnectPacket.from_stream(reader)
  File "/home/homeassistant/.homeassistant/deps/lib/python3.5/site-packages/hbmqtt/mqtt/packet.py", line 232, in from_stream
    payload = yield from cls.PAYLOAD.from_stream(reader, fixed_header, variable_header)
  File "/home/homeassistant/.homeassistant/deps/lib/python3.5/site-packages/hbmqtt/mqtt/connect.py", line 167, in from_stream
    payload.client_id = yield from decode_string(reader)
  File "/home/homeassistant/.homeassistant/deps/lib/python3.5/site-packages/hbmqtt/codecs.py", line 68, in decode_string
    byte_str = yield from read_or_raise(reader, str_length[0])
  File "/home/homeassistant/.homeassistant/deps/lib/python3.5/site-packages/hbmqtt/codecs.py", line 52, in read_or_raise
    data = yield from reader.read(n)
  File "/home/homeassistant/.homeassistant/deps/lib/python3.5/site-packages/hbmqtt/adapters.py", line 146, in read
    data = yield from self._reader.readexactly(n)
  File "/usr/local/lib/python3.5/asyncio/streams.py", line 666, in readexactly
    raise IncompleteReadError(incomplete, n)
asyncio.streams.IncompleteReadError: 50 bytes read on a total of 768 expected bytes
2018-07-31 12:44:27 ERROR (MainThread) [homeassistant.core] Error doing job: Task exception was never retrieved
Traceback (most recent call last):
  File "/usr/local/lib/python3.5/asyncio/tasks.py", line 241, in _step
    result = coro.throw(exc)
  File "/home/homeassistant/.homeassistant/deps/lib/python3.5/site-packages/hbmqtt/broker.py", line 342, in stream_connected
    yield from self.client_connected(listener_name, StreamReaderAdapter(reader), StreamWriterAdapter(writer))
  File "/home/homeassistant/.homeassistant/deps/lib/python3.5/site-packages/hbmqtt/broker.py", line 357, in client_connected
    handler, client_session = yield from BrokerProtocolHandler.init_from_connect(reader, writer, self.plugins_manager, loop=self._loop)
  File "/home/homeassistant/.homeassistant/deps/lib/python3.5/site-packages/hbmqtt/mqtt/protocol/broker_handler.py", line 129, in init_from_connect
    connect = yield from ConnectPacket.from_stream(reader)
  File "/home/homeassistant/.homeassistant/deps/lib/python3.5/site-packages/hbmqtt/mqtt/packet.py", line 225, in from_stream
    fixed_header = yield from cls.FIXED_HEADER.from_stream(reader)
  File "/home/homeassistant/.homeassistant/deps/lib/python3.5/site-packages/hbmqtt/mqtt/packet.py", line 104, in from_stream
    byte1 = yield from read_or_raise(reader, 1)
  File "/home/homeassistant/.homeassistant/deps/lib/python3.5/site-packages/hbmqtt/codecs.py", line 52, in read_or_raise
    data = yield from reader.read(n)
  File "/home/homeassistant/.homeassistant/deps/lib/python3.5/site-packages/hbmqtt/adapters.py", line 146, in read
    data = yield from self._reader.readexactly(n)
  File "/usr/local/lib/python3.5/asyncio/streams.py", line 668, in readexactly
    yield from self._wait_for_data('readexactly')
  File "/usr/local/lib/python3.5/asyncio/streams.py", line 458, in _wait_for_data
    yield from self._waiter
  File "/usr/local/lib/python3.5/asyncio/futures.py", line 380, in __iter__
    yield self  # This tells Task to wait for completion.
  File "/usr/local/lib/python3.5/asyncio/tasks.py", line 304, in _wakeup
    future.result()
  File "/usr/local/lib/python3.5/asyncio/futures.py", line 293, in result
    raise self._exception
  File "/usr/local/lib/python3.5/asyncio/selector_events.py", line 723, in _read_ready
    data = self._sock.recv(self.max_size)
ConnectionResetError: [Errno 104] Connection reset by peer
2018-07-31 12:44:27 WARNING (MainThread) [hbmqtt.mqtt.protocol.handler] BrokerProtocolHandler Unhandled exception in reader coro: ConnectionResetError(104, 'Connection reset by peer')
2018-07-31 12:44:31 ERROR (MainThread) [homeassistant.core] Error doing job: Task exception was never retrieved
Traceback (most recent call last):
  File "/usr/local/lib/python3.5/asyncio/tasks.py", line 241, in _step
    result = coro.throw(exc)
  File "/home/homeassistant/.homeassistant/deps/lib/python3.5/site-packages/hbmqtt/broker.py", line 342, in stream_connected
    yield from self.client_connected(listener_name, StreamReaderAdapter(reader), StreamWriterAdapter(writer))
  File "/home/homeassistant/.homeassistant/deps/lib/python3.5/site-packages/hbmqtt/broker.py", line 357, in client_connected
    handler, client_session = yield from BrokerProtocolHandler.init_from_connect(reader, writer, self.plugins_manager, loop=self._loop)
  File "/home/homeassistant/.homeassistant/deps/lib/python3.5/site-packages/hbmqtt/mqtt/protocol/broker_handler.py", line 129, in init_from_connect
    connect = yield from ConnectPacket.from_stream(reader)
  File "/home/homeassistant/.homeassistant/deps/lib/python3.5/site-packages/hbmqtt/mqtt/packet.py", line 228, in from_stream
    variable_header = yield from cls.VARIABLE_HEADER.from_stream(reader, fixed_header)
  File "/home/homeassistant/.homeassistant/deps/lib/python3.5/site-packages/hbmqtt/mqtt/connect.py", line 105, in from_stream
    protocol_name = yield from decode_string(reader)
  File "/home/homeassistant/.homeassistant/deps/lib/python3.5/site-packages/hbmqtt/codecs.py", line 68, in decode_string
    byte_str = yield from read_or_raise(reader, str_length[0])
  File "/home/homeassistant/.homeassistant/deps/lib/python3.5/site-packages/hbmqtt/codecs.py", line 52, in read_or_raise
    data = yield from reader.read(n)
  File "/home/homeassistant/.homeassistant/deps/lib/python3.5/site-packages/hbmqtt/adapters.py", line 146, in read
    data = yield from self._reader.readexactly(n)
  File "/usr/local/lib/python3.5/asyncio/streams.py", line 668, in readexactly
    yield from self._wait_for_data('readexactly')
  File "/usr/local/lib/python3.5/asyncio/streams.py", line 458, in _wait_for_data
    yield from self._waiter
  File "/usr/local/lib/python3.5/asyncio/futures.py", line 380, in __iter__
    yield self  # This tells Task to wait for completion.
  File "/usr/local/lib/python3.5/asyncio/tasks.py", line 304, in _wakeup
    future.result()
  File "/usr/local/lib/python3.5/asyncio/futures.py", line 293, in result
    raise self._exception
  File "/usr/local/lib/python3.5/asyncio/selector_events.py", line 723, in _read_ready
    data = self._sock.recv(self.max_size)
ConnectionResetError: [Errno 104] Connection reset by peer
2018-07-31 12:44:34 ERROR (MainThread) [homeassistant.core] Error doing job: Task exception was never retrieved
Traceback (most recent call last):
  File "/usr/local/lib/python3.5/asyncio/tasks.py", line 241, in _step
    result = coro.throw(exc)
  File "/home/homeassistant/.homeassistant/deps/lib/python3.5/site-packages/hbmqtt/broker.py", line 342, in stream_connected
    yield from self.client_connected(listener_name, StreamReaderAdapter(reader), StreamWriterAdapter(writer))
  File "/home/homeassistant/.homeassistant/deps/lib/python3.5/site-packages/hbmqtt/broker.py", line 357, in client_connected
    handler, client_session = yield from BrokerProtocolHandler.init_from_connect(reader, writer, self.plugins_manager, loop=self._loop)
  File "/home/homeassistant/.homeassistant/deps/lib/python3.5/site-packages/hbmqtt/mqtt/protocol/broker_handler.py", line 129, in init_from_connect
    connect = yield from ConnectPacket.from_stream(reader)
  File "/home/homeassistant/.homeassistant/deps/lib/python3.5/site-packages/hbmqtt/mqtt/packet.py", line 228, in from_stream
    variable_header = yield from cls.VARIABLE_HEADER.from_stream(reader, fixed_header)
  File "/home/homeassistant/.homeassistant/deps/lib/python3.5/site-packages/hbmqtt/mqtt/connect.py", line 105, in from_stream
    protocol_name = yield from decode_string(reader)
  File "/home/homeassistant/.homeassistant/deps/lib/python3.5/site-packages/hbmqtt/codecs.py", line 68, in decode_string
    byte_str = yield from read_or_raise(reader, str_length[0])
  File "/home/homeassistant/.homeassistant/deps/lib/python3.5/site-packages/hbmqtt/codecs.py", line 52, in read_or_raise
    data = yield from reader.read(n)
  File "/home/homeassistant/.homeassistant/deps/lib/python3.5/site-packages/hbmqtt/adapters.py", line 146, in read
    data = yield from self._reader.readexactly(n)
  File "/usr/local/lib/python3.5/asyncio/streams.py", line 668, in readexactly
    yield from self._wait_for_data('readexactly')
  File "/usr/local/lib/python3.5/asyncio/streams.py", line 458, in _wait_for_data
    yield from self._waiter
  File "/usr/local/lib/python3.5/asyncio/futures.py", line 380, in __iter__
    yield self  # This tells Task to wait for completion.
  File "/usr/local/lib/python3.5/asyncio/tasks.py", line 304, in _wakeup
    future.result()
  File "/usr/local/lib/python3.5/asyncio/futures.py", line 293, in result
    raise self._exception
  File "/usr/local/lib/python3.5/asyncio/selector_events.py", line 723, in _read_ready
    data = self._sock.recv(self.max_size)
ConnectionResetError: [Errno 104] Connection reset by peer
2018-07-31 22:41:59 ERROR (Thread-19) [datadog.dogstatsd] Failed to send packet with a newly bound socket
Traceback (most recent call last):
  File "/home/homeassistant/.homeassistant/deps/lib/python3.5/site-packages/datadog/dogstatsd/base.py", line 267, in _send_to_server
    (self.socket or self.get_socket()).send(packet.encode(self.encoding))
ConnectionRefusedError: [Errno 111] Connection refused

During handling of the above exception, another exception occurred:

Traceback (most recent call last):
  File "/home/homeassistant/.homeassistant/deps/lib/python3.5/site-packages/datadog/dogstatsd/base.py", line 274, in _send_to_server
    self.get_socket().send(packet.encode(self.encoding))
ConnectionRefusedError: [Errno 111] Connection refused
2018-08-01 03:31:07 ERROR (Thread-6) [datadog.dogstatsd] Failed to send packet with a newly bound socket
Traceback (most recent call last):
  File "/home/homeassistant/.homeassistant/deps/lib/python3.5/site-packages/datadog/dogstatsd/base.py", line 267, in _send_to_server
    (self.socket or self.get_socket()).send(packet.encode(self.encoding))
ConnectionRefusedError: [Errno 111] Connection refused

During handling of the above exception, another exception occurred:

Traceback (most recent call last):
  File "/home/homeassistant/.homeassistant/deps/lib/python3.5/site-packages/datadog/dogstatsd/base.py", line 274, in _send_to_server
    self.get_socket().send(packet.encode(self.encoding))
ConnectionRefusedError: [Errno 111] Connection refused
2018-08-01 05:17:29 ERROR (Thread-17) [datadog.dogstatsd] Failed to send packet with a newly bound socket
Traceback (most recent call last):
  File "/home/homeassistant/.homeassistant/deps/lib/python3.5/site-packages/datadog/dogstatsd/base.py", line 267, in _send_to_server
    (self.socket or self.get_socket()).send(packet.encode(self.encoding))
ConnectionRefusedError: [Errno 111] Connection refused

During handling of the above exception, another exception occurred:

Traceback (most recent call last):
  File "/home/homeassistant/.homeassistant/deps/lib/python3.5/site-packages/datadog/dogstatsd/base.py", line 274, in _send_to_server
    self.get_socket().send(packet.encode(self.encoding))
ConnectionRefusedError: [Errno 111] Connection refused
2018-08-01 05:34:30 ERROR (Thread-21) [datadog.dogstatsd] Failed to send packet with a newly bound socket
Traceback (most recent call last):
  File "/home/homeassistant/.homeassistant/deps/lib/python3.5/site-packages/datadog/dogstatsd/base.py", line 267, in _send_to_server
    (self.socket or self.get_socket()).send(packet.encode(self.encoding))
ConnectionRefusedError: [Errno 111] Connection refused

During handling of the above exception, another exception occurred:

Traceback (most recent call last):
  File "/home/homeassistant/.homeassistant/deps/lib/python3.5/site-packages/datadog/dogstatsd/base.py", line 274, in _send_to_server
    self.get_socket().send(packet.encode(self.encoding))
ConnectionRefusedError: [Errno 111] Connection refused
2018-08-01 07:21:22 ERROR (Thread-8) [datadog.dogstatsd] Failed to send packet with a newly bound socket
Traceback (most recent call last):
  File "/home/homeassistant/.homeassistant/deps/lib/python3.5/site-packages/datadog/dogstatsd/base.py", line 267, in _send_to_server
    (self.socket or self.get_socket()).send(packet.encode(self.encoding))
ConnectionRefusedError: [Errno 111] Connection refused

During handling of the above exception, another exception occurred:

Traceback (most recent call last):
  File "/home/homeassistant/.homeassistant/deps/lib/python3.5/site-packages/datadog/dogstatsd/base.py", line 274, in _send_to_server
    self.get_socket().send(packet.encode(self.encoding))
ConnectionRefusedError: [Errno 111] Connection refused
2018-08-01 21:45:45 ERROR (Thread-15) [datadog.dogstatsd] Failed to send packet with a newly bound socket
Traceback (most recent call last):
  File "/home/homeassistant/.homeassistant/deps/lib/python3.5/site-packages/datadog/dogstatsd/base.py", line 267, in _send_to_server
    (self.socket or self.get_socket()).send(packet.encode(self.encoding))
ConnectionRefusedError: [Errno 111] Connection refused

During handling of the above exception, another exception occurred:

Traceback (most recent call last):
  File "/home/homeassistant/.homeassistant/deps/lib/python3.5/site-packages/datadog/dogstatsd/base.py", line 274, in _send_to_server
    self.get_socket().send(packet.encode(self.encoding))
ConnectionRefusedError: [Errno 111] Connection refused
2018-08-01 22:19:49 ERROR (Thread-3) [datadog.dogstatsd] Failed to send packet with a newly bound socket
Traceback (most recent call last):
  File "/home/homeassistant/.homeassistant/deps/lib/python3.5/site-packages/datadog/dogstatsd/base.py", line 267, in _send_to_server
    (self.socket or self.get_socket()).send(packet.encode(self.encoding))
ConnectionRefusedError: [Errno 111] Connection refused

During handling of the above exception, another exception occurred:

Traceback (most recent call last):
  File "/home/homeassistant/.homeassistant/deps/lib/python3.5/site-packages/datadog/dogstatsd/base.py", line 274, in _send_to_server
    self.get_socket().send(packet.encode(self.encoding))
ConnectionRefusedError: [Errno 111] Connection refused
2018-08-02 05:55:15 ERROR (Thread-3) [datadog.dogstatsd] Failed to send packet with a newly bound socket
Traceback (most recent call last):
  File "/home/homeassistant/.homeassistant/deps/lib/python3.5/site-packages/datadog/dogstatsd/base.py", line 267, in _send_to_server
    (self.socket or self.get_socket()).send(packet.encode(self.encoding))
ConnectionRefusedError: [Errno 111] Connection refused

During handling of the above exception, another exception occurred:

Traceback (most recent call last):
  File "/home/homeassistant/.homeassistant/deps/lib/python3.5/site-packages/datadog/dogstatsd/base.py", line 274, in _send_to_server
    self.get_socket().send(packet.encode(self.encoding))
ConnectionRefusedError: [Errno 111] Connection refused
2018-08-02 08:06:53 ERROR (Thread-5) [datadog.dogstatsd] Failed to send packet with a newly bound socket
Traceback (most recent call last):
  File "/home/homeassistant/.homeassistant/deps/lib/python3.5/site-packages/datadog/dogstatsd/base.py", line 267, in _send_to_server
    (self.socket or self.get_socket()).send(packet.encode(self.encoding))
ConnectionRefusedError: [Errno 111] Connection refused

During handling of the above exception, another exception occurred:

Traceback (most recent call last):
  File "/home/homeassistant/.homeassistant/deps/lib/python3.5/site-packages/datadog/dogstatsd/base.py", line 274, in _send_to_server
    self.get_socket().send(packet.encode(self.encoding))
ConnectionRefusedError: [Errno 111] Connection refused
2018-08-02 11:32:55 ERROR (Thread-4) [datadog.dogstatsd] Failed to send packet with a newly bound socket
Traceback (most recent call last):
  File "/home/homeassistant/.homeassistant/deps/lib/python3.5/site-packages/datadog/dogstatsd/base.py", line 267, in _send_to_server
    (self.socket or self.get_socket()).send(packet.encode(self.encoding))
ConnectionRefusedError: [Errno 111] Connection refused

During handling of the above exception, another exception occurred:

Traceback (most recent call last):
  File "/home/homeassistant/.homeassistant/deps/lib/python3.5/site-packages/datadog/dogstatsd/base.py", line 274, in _send_to_server
    self.get_socket().send(packet.encode(self.encoding))
ConnectionRefusedError: [Errno 111] Connection refused
2018-08-02 17:06:30 ERROR (Thread-3) [datadog.dogstatsd] Failed to send packet with a newly bound socket
Traceback (most recent call last):
  File "/home/homeassistant/.homeassistant/deps/lib/python3.5/site-packages/datadog/dogstatsd/base.py", line 267, in _send_to_server
    (self.socket or self.get_socket()).send(packet.encode(self.encoding))
ConnectionRefusedError: [Errno 111] Connection refused

During handling of the above exception, another exception occurred:

Traceback (most recent call last):
  File "/home/homeassistant/.homeassistant/deps/lib/python3.5/site-packages/datadog/dogstatsd/base.py", line 274, in _send_to_server
    self.get_socket().send(packet.encode(self.encoding))
ConnectionRefusedError: [Errno 111] Connection refused
2018-08-03 00:29:11 ERROR (MainThread) [homeassistant.core] Timer got out of sync. Resetting
2018-08-03 00:30:14 ERROR (MainThread) [homeassistant.core] Timer got out of sync. Resetting
2018-08-03 00:31:01 WARNING (MainThread) [homeassistant.core] Unable to find service sensor/turn_on
2018-08-03 00:31:10 WARNING (MainThread) [homeassistant.core] Unable to find service sensor/turn_off
2018-08-03 01:02:30 ERROR (Thread-15) [datadog.dogstatsd] Failed to send packet with a newly bound socket
Traceback (most recent call last):
  File "/home/homeassistant/.homeassistant/deps/lib/python3.5/site-packages/datadog/dogstatsd/base.py", line 267, in _send_to_server
    (self.socket or self.get_socket()).send(packet.encode(self.encoding))
ConnectionRefusedError: [Errno 111] Connection refused

During handling of the above exception, another exception occurred:

Traceback (most recent call last):
  File "/home/homeassistant/.homeassistant/deps/lib/python3.5/site-packages/datadog/dogstatsd/base.py", line 274, in _send_to_server
    self.get_socket().send(packet.encode(self.encoding))
ConnectionRefusedError: [Errno 111] Connection refused
2018-08-03 01:15:56 ERROR (Thread-3) [datadog.dogstatsd] Failed to send packet with a newly bound socket
Traceback (most recent call last):
  File "/home/homeassistant/.homeassistant/deps/lib/python3.5/site-packages/datadog/dogstatsd/base.py", line 267, in _send_to_server
    (self.socket or self.get_socket()).send(packet.encode(self.encoding))
ConnectionRefusedError: [Errno 111] Connection refused

During handling of the above exception, another exception occurred:

Traceback (most recent call last):
  File "/home/homeassistant/.homeassistant/deps/lib/python3.5/site-packages/datadog/dogstatsd/base.py", line 274, in _send_to_server
    self.get_socket().send(packet.encode(self.encoding))
ConnectionRefusedError: [Errno 111] Connection refused
2018-08-03 04:02:44 ERROR (Thread-11) [datadog.dogstatsd] Failed to send packet with a newly bound socket
Traceback (most recent call last):
  File "/home/homeassistant/.homeassistant/deps/lib/python3.5/site-packages/datadog/dogstatsd/base.py", line 267, in _send_to_server
    (self.socket or self.get_socket()).send(packet.encode(self.encoding))
ConnectionRefusedError: [Errno 111] Connection refused

During handling of the above exception, another exception occurred:

Traceback (most recent call last):
  File "/home/homeassistant/.homeassistant/deps/lib/python3.5/site-packages/datadog/dogstatsd/base.py", line 274, in _send_to_server
    self.get_socket().send(packet.encode(self.encoding))
ConnectionRefusedError: [Errno 111] Connection refused
2018-08-03 07:11:53 ERROR (MainThread) [hbmqtt.broker] Invalid connection from (client @=71.6.165.200:54871) : [MQTT-3.1.2-1] Incorrect protocol name: "MQIsdp"
2018-08-03 07:12:06 ERROR (MainThread) [homeassistant.core] Error doing job: Task exception was never retrieved
Traceback (most recent call last):
  File "/usr/local/lib/python3.5/asyncio/tasks.py", line 239, in _step
    result = coro.send(None)
  File "/home/homeassistant/.homeassistant/deps/lib/python3.5/site-packages/hbmqtt/broker.py", line 342, in stream_connected
    yield from self.client_connected(listener_name, StreamReaderAdapter(reader), StreamWriterAdapter(writer))
  File "/home/homeassistant/.homeassistant/deps/lib/python3.5/site-packages/hbmqtt/broker.py", line 357, in client_connected
    handler, client_session = yield from BrokerProtocolHandler.init_from_connect(reader, writer, self.plugins_manager, loop=self._loop)
  File "/home/homeassistant/.homeassistant/deps/lib/python3.5/site-packages/hbmqtt/mqtt/protocol/broker_handler.py", line 129, in init_from_connect
    connect = yield from ConnectPacket.from_stream(reader)
  File "/home/homeassistant/.homeassistant/deps/lib/python3.5/site-packages/hbmqtt/mqtt/packet.py", line 225, in from_stream
    fixed_header = yield from cls.FIXED_HEADER.from_stream(reader)
  File "/home/homeassistant/.homeassistant/deps/lib/python3.5/site-packages/hbmqtt/mqtt/packet.py", line 104, in from_stream
    byte1 = yield from read_or_raise(reader, 1)
  File "/home/homeassistant/.homeassistant/deps/lib/python3.5/site-packages/hbmqtt/codecs.py", line 52, in read_or_raise
    data = yield from reader.read(n)
  File "/home/homeassistant/.homeassistant/deps/lib/python3.5/site-packages/hbmqtt/adapters.py", line 146, in read
    data = yield from self._reader.readexactly(n)
  File "/usr/local/lib/python3.5/asyncio/streams.py", line 666, in readexactly
    raise IncompleteReadError(incomplete, n)
asyncio.streams.IncompleteReadError: 0 bytes read on a total of 1 expected bytes
2018-08-03 16:11:28 ERROR (MainThread) [homeassistant.core] Error doing job: Task exception was never retrieved
Traceback (most recent call last):
  File "/usr/local/lib/python3.5/asyncio/tasks.py", line 241, in _step
    result = coro.throw(exc)
  File "/usr/local/lib/python3.5/site-packages/homeassistant/components/discovery.py", line 167, in scan_devices
    results = await hass.async_add_job(_discover, netdisco)
  File "/usr/local/lib/python3.5/asyncio/futures.py", line 380, in __iter__
    yield self  # This tells Task to wait for completion.
  File "/usr/local/lib/python3.5/asyncio/tasks.py", line 304, in _wakeup
    future.result()
  File "/usr/local/lib/python3.5/asyncio/futures.py", line 293, in result
    raise self._exception
  File "/usr/local/lib/python3.5/concurrent/futures/thread.py", line 55, in run
    result = self.fn(*self.args, **self.kwargs)
  File "/usr/local/lib/python3.5/site-packages/homeassistant/components/discovery.py", line 193, in _discover
    netdisco.scan()
  File "/home/homeassistant/.homeassistant/deps/lib/python3.5/site-packages/netdisco/discovery.py", line 52, in scan
  File "/home/homeassistant/.homeassistant/deps/lib/python3.5/site-packages/netdisco/discovery.py", line 110, in _load_device_support
FileNotFoundError: [Errno 2] No such file or directory: '/home/homeassistant/.homeassistant/deps/lib/python3.5/site-packages/netdisco/discoverables'
